<?xml version="1.0"?>

<robot name="jaguarbot" xmlns:xacro="http://www.ros.org/wiki/xacro">
    <material name="white">
        <color rgba="1 1 1 1"/>    
    </material>

    <material name="black">
        <color rgba="0 0 0 1"/>
    </material>
    
    <!-- LINKS -->
    <!-- CHASIS -->
    <link name="chasis">
        <inertial>
            <origin xyz="0.0 0.0 0.0" rpy="0.0 0.0 0.0"/>
            <mass value="5"/>
            <inertia ixx="0.04" ixy="0.0" ixz="0.0" iyy="0.1" iyz="0.0" izz="0.1"/>
        </inertial>

        <collision>            
            <geometry>
                <box size="0.5 0.3 0.3"/>
            </geometry>
        </collision>

        <visual>
            <origin rpy="0 0 0" xyz="0 0 0"/>
            <geometry>
                <box size="0.5 0.3 0.3"/>
            </geometry>
            <material name="white"/>
        </visual>        
    </link>
    
    <!-- WHEELS TO THE LEFT -->
    <!-- LEFT WHEEL 1 -->
    <link name="left_wheel_1">
        <inertial>
            <origin xyz="0.0 0.0 0.0" rpy="0.0 0.0 0.0"/>
            <mass value="0.3"/>
            <inertia ixx="0.01" ixy="0.0" ixz="0.0" iyy="0.01" iyz="0.0" izz="0.01"/>
        </inertial>
        
        <collision>            
            <geometry>
                <cylinder radius="0.03" length="0.03"/>
            </geometry>
        </collision>

        <visual>
            <origin xyz="0.0 0.0 0.015" rpy="0.0 0.0 0.0"/>
            <geometry>
                <cylinder radius="0.03" length="0.03"/>
            </geometry>
            <material name="black"/>
        </visual>
    </link>

    <!-- LEFT WHEEL 2 -->
    <link name="left_wheel_2">
        <inertial>
            <origin xyz="0.0 0.0 0.0" rpy="0.0 0.0 0.0"/>
            <mass value="0.3"/>
            <inertia ixx="0.01" ixy="0.0" ixz="0.0" iyy="0.01" iyz="0.0" izz="0.01"/>
        </inertial>

        <collision>
            <geometry>
                <cylinder radius="0.03" length="0.03"/>
            </geometry>
        </collision>

        <visual>
            <origin xyz="0.0 0.0 0.015" rpy="0.0 0.0 0.0"/>
            <geometry>
                <cylinder radius="0.03" length="0.03"/>
            </geometry>
            <material name="black"/>
        </visual>
    </link>

    <!-- LEFT WHEEL 3 -->
    <link name="left_wheel_3">
        <inertial>
            <origin xyz="0.0 0.0 0.0" rpy="0.0 0.0 0.0"/>
            <mass value="0.3"/>
            <inertia ixx="0.01" ixy="0.0" ixz="0.0" iyy="0.01" iyz="0.0" izz="0.01"/>
        </inertial>

        <collision>
            <geometry>
                <cylinder radius="0.03" length="0.03"/>
            </geometry>
        </collision>

        <visual>
            <origin xyz="0.0 0.0 0.015" rpy="0.0 0.0 0.0"/>
            <geometry>
                <cylinder radius="0.03" length="0.03"/>
            </geometry>
            <material name="black"/>
        </visual>
    </link>

    <!-- WHEELS TO THE RIGHT -->
    <!-- RIGHT WHEEL 1 -->
    <link name="right_wheel_1">
        <inertial>
            <origin xyz="0.0 0.0 0.0" rpy="0.0 0.0 0.0"/>
            <mass value="0.3"/>
            <inertia ixx="0.01" ixy="0.0" ixz="0.0" iyy="0.01" iyz="0.0" izz="0.01"/>
        </inertial>

        <collision>
            <geometry>
                <cylinder radius="0.03" length="0.03"/>
            </geometry>
        </collision>

        <visual>
            <origin xyz="0.0 0.0 0.015" rpy="0.0 0.0 0.0"/>
            <geometry>
                <cylinder radius="0.03" length="0.03"/>
            </geometry>
            <material name="black"/>
        </visual>
    </link>

    <!-- RIGHT WHEEL 2 -->
    <link name="right_wheel_2">
        <inertial>
            <origin xyz="0.0 0.0 0.0" rpy="0.0 0.0 0.0"/>
            <mass value="0.3"/>
            <inertia ixx="0.01" ixy="0.0" ixz="0.0" iyy="0.01" iyz="0.0" izz="0.01"/>
        </inertial>

        <collision>
            <geometry>
                <cylinder radius="0.03" length="0.03"/>
            </geometry>
        </collision>

        <visual>
            <origin xyz="0.0 0.0 0.015" rpy="0.0 0.0 0.0"/>
            <geometry>
                <cylinder radius="0.03" length="0.03"/>
            </geometry>
            <material name="black"/>
        </visual>
    </link>

    <!-- RIGHT WHEEL 3 -->
    <link name="right_wheel_3">
        <inertial>
            <origin xyz="0.0 0.0 0.0" rpy="0.0 0.0 0.0"/>
            <mass value="0.3"/>
            <inertia ixx="0.01" ixy="0.0" ixz="0.0" iyy="0.01" iyz="0.0" izz="0.01"/>
        </inertial>
        
        <collision>
            <geometry>
                <cylinder radius="0.03" length="0.03"/>
            </geometry>
        </collision>

        <visual>
            <origin xyz="0.0 0.0 0.015" rpy="0.0 0.0 0.0"/>
            <geometry>
                <cylinder radius="0.03" length="0.03"/>
            </geometry>
            <material name="black"/>
        </visual>
    </link>

    <!-- JOINTS -->
    <!-- LEFT JOINT 1 -->
    <joint name="left_joint_1" type="continuous">
        <origin xyz="0.25 0.15 -0.15" rpy="-1.57075 0.0 0.0"/>
        <parent link="chasis"/>
        <child link="left_wheel_1"/>
        <axis xyz="0.0 0.0 1"/>
        <hardwareInterface>hardware_interface/EffortJointInterface</hardwareInterface>
    </joint>

    <!-- LEFT JOINT 2 -->
    <joint name="left_joint_2" type="continuous">
        <origin xyz="0.0 0.15 -0.15" rpy="-1.57075 0.0 0.0"/>
        <parent link="chasis"/>
        <child link="left_wheel_2"/>
        <axis xyz="0.0 0.0 1"/>
        <hardwareInterface>hardware_interface/EffortJointInterface</hardwareInterface>
    </joint>

    <!-- LEFT JOINT 3 -->
    <joint name="left_joint_3" type="continuous">
        <origin xyz="-0.25 0.15 -0.15" rpy="-1.57075 0.0 0.0"/>
        <parent link="chasis"/>
        <child link="left_wheel_3"/>
        <axis xyz="0.0 0.0 1"/>
        <hardwareInterface>hardware_interface/EffortJointInterface</hardwareInterface>
    </joint>

    <!-- RIGHT JOINT 1 -->
    <joint name="right_joint_1" type="continuous">
        <origin xyz="0.25 -0.15 -0.15" rpy="1.57075 0.0 0.0"/>
        <parent link="chasis"/>
        <child link="right_wheel_1"/>
        <axis xyz="0.0 0.0 1"/>
        <hardwareInterface>hardware_interface/EffortJointInterface</hardwareInterface>
    </joint>

    <!-- RIGHT JOINT 2 -->
    <joint name="right_joint_2" type="continuous">
        <origin xyz="0.0 -0.15 -0.15" rpy="1.57075 0.0 0.0"/>
        <parent link="chasis"/>
        <child link="right_wheel_2"/>
        <axis xyz="0.0 0.0 1"/>
        <hardwareInterface>hardware_interface/EffortJointInterface</hardwareInterface>
    </joint>

    <!-- RIGHT JOINT 3 -->
    <joint name="right_joint_3" type="continuous">
        <origin xyz="-0.25 -0.15 -0.15" rpy="1.57075 0.0 0.0"/>
        <parent link="chasis"/>
        <child link="right_wheel_3"/>
        <axis xyz="0.0 0.0 1"/>
        <hardwareInterface>hardware_interface/EffortJointInterface</hardwareInterface>
    </joint>

    <!-- TRANSMISSIONS -->
    <!-- LEFT MOTOR 1 -->
    <transmission name="left_trans_1">
        <type>transmission_interface/SimpleTransmission</type>
        <joint name="left_joint_1">
            <hardwareInterface>hardware_interface/EffortJointInterface</hardwareInterface>
        </joint>
        <actuator name="left_motor_1">
            <mechanicalReduction>1.0</mechanicalReduction>
        </actuator>
    </transmission>

    <!-- LEFT MOTOR 2 -->
    <transmission name="left_trans_2">
        <type>transmission_interface/SimpleTransmission</type>
        <joint name="left_joint_2">
            <hardwareInterface>hardware_interface/EffortJointInterface</hardwareInterface>
        </joint>
        <actuator name="left_motor_2">
            <mechanicalReduction>1.0</mechanicalReduction>
        </actuator>
    </transmission>
    
    <!-- LEFT MOTOR 3 -->
    <transmission name="left_trans_3">
        <type>transmission_interface/SimpleTransmission</type>
        <joint name="left_joint_3">
            <hardwareInterface>hardware_interface/EffortJointInterface</hardwareInterface>
        </joint>
        <actuator name="left_motor_3">
            <mechanicalReduction>1.0</mechanicalReduction>
        </actuator>
    </transmission>

    <!-- RIGHT MOTOR 1 -->
    <transmission name="right_trans_1">
        <type>transmission_interface/SimpleTransmission</type>
        <joint name="right_joint_1">
            <hardwareInterface>hardware_interface/EffortJointInterface</hardwareInterface>
        </joint>
        <actuator name="right_motor_1">
            <mechanicalReduction>1.0</mechanicalReduction>
        </actuator>
    </transmission>

    <!-- RIGHT MOTOR 2 -->
    <transmission name="right_trans_2">
        <type>transmission_interface/SimpleTransmission</type>
        <joint name="right_joint_2">
            <hardwareInterface>hardware_interface/EffortJointInterface</hardwareInterface>
        </joint>
        <actuator name="right_motor_2">
            <mechanicalReduction>1.0</mechanicalReduction>
        </actuator>
    </transmission>

    <!-- RIGHT MOTOR 3 -->
    <transmission name="right_trans_3">
        <type>transmission_interface/SimpleTransmission</type>
        <joint name="right_joint_3">
            <hardwareInterface>hardware_interface/EffortJointInterface</hardwareInterface>
        </joint>
        <actuator name="right_motor_3">
            <mechanicalReduction>1.0</mechanicalReduction>
        </actuator>
    </transmission>

    <!-- GAZEBO PLUGINS -->
    <gazebo>
        <plugin name="gazebo_ros_control" filename="libgazebo_ros_control.so">
            <robotNamespace>/jaguarbot</robotNamespace>
        </plugin>
    </gazebo>
</robot>